<?xml version="1.0"?>
<robot xmlns:xacro="http://www.ros.org/wiki/xacro" name="snake">
	
<xacro:property name="M_PI" value="3.14"/>
<xacro:property name="body_l" value="0.2"/>
<xacro:property name="body_r" value="0.1"/>
<xacro:property name="color" value="40 50 255 100"/>
<xacro:property name="mass" value="1"/>
<xacro:property name="IX" value="0.01"/>
<xacro:property name="IY" value="0.01"/>
<xacro:property name="IZ" value="0.01"/>

	<!--basic xyz-->
	<link name="link0"/>

	<joint name="joint0" type="fixed">
		<axis xyz="1 0 0"/>
		<parent link="link0"/>
		<child link="link1"/>
		<origin rpy="${0.5*M_PI} 0 0" xyz="0 ${0.5*body_l} ${0.5*body_r}"/>
	</joint> 

<xacro:macro name="model" params="name_link name_joint r_x r_y after_link I1 I2">
	<link name="${name_link}" >
		<visual>
			<origin rpy="0 0 0" xyz="0 0 ${0.8*body_l}"/>
			<geometry>
				<cylinder length="${body_l}" radius="${body_r}"/>
			</geometry>
			<material name="xwy">
				<color rgba="${color}"/>
			</material>
		</visual>
		<collision>
			<origin rpy="0 0 0" xyz="0 0 ${0.8*body_l}"/>
			<geometry>
				<cylinder length="${body_l}" radius="${body_r}"/>
			</geometry>
		</collision>
		<inertial>
			<origin rpy="0 0 0" xyz="0 0 ${0.8*body_l}"/>
			<mass value="${mass}"/>
			<inertia ixx="${I1}" ixy="0.0" ixz="0.0" iyy="${I2}" iyz="0.0" izz="${IZ}"/>
		</inertial>
	</link>

	<gazebo reference="${name_link}">
		<material>Gazebo/Blue</material>
	</gazebo>
	
	<joint name="${name_joint}" type="revolute">
		<axis xyz="${r_x} ${r_y} 0"/>
		<limit effort="500" lower="-0.78540" upper="0.78540" velocity="2"/>
		<parent link="${name_link}"/>
		<child link="${after_link}"/>
		<origin rpy="0 0 0" xyz="0 0 ${1.3*body_l}"/>
	</joint>  
      

	
	<transmission name="${name_link}_tran">
		<type>transmission_interface/SimpleTransmission</type>
		<joint name="${name_joint}">
			<hardwareInterface>EffortJointInterface</hardwareInterface>
		</joint>
		<actuator name="${name_joint}_motor">
			<hardwareInterface>EffortJointInterface</hardwareInterface>
			<mechanicalReduction>1</mechanicalReduction>
		</actuator>
	</transmission>

	<gazebo>
		<plugin name="gazebo_ros_control" filename="libgazebo_ros_control.so">
			<robotNamespace>/snake</robotNamespace>
		</plugin>
	</gazebo>
	<gazebo>
		  <plugin name="joint_state_publisher" filename="libgazebo_ros_joint_state_publisher.so">
			  <jointName>${name_joint}</jointName>
		  </plugin>
	</gazebo>

</xacro:macro>

<xacro:model name_link="link1" name_joint="joint1" r_x="0" r_y="1" after_link="link2" I1="${IX}" I2="${IY}"/>
<xacro:model name_link="link2" name_joint="joint2" r_x="1" r_y="0" after_link="link3" I1="${IY}" I2="${IX}"/>
<xacro:model name_link="link3" name_joint="joint3" r_x="0" r_y="1" after_link="link4" I1="${IX}" I2="${IY}"/>
<xacro:model name_link="link4" name_joint="joint4" r_x="1" r_y="0" after_link="link5" I1="${IY}" I2="${IX}"/>
<xacro:model name_link="link5" name_joint="joint5" r_x="0" r_y="1" after_link="link6" I1="${IX}" I2="${IY}"/>
<xacro:model name_link="link6" name_joint="joint6" r_x="1" r_y="0" after_link="link7" I1="${IY}" I2="${IX}"/>
<xacro:model name_link="link7" name_joint="joint7" r_x="0" r_y="1" after_link="link8" I1="${IX}" I2="${IY}"/>
<xacro:model name_link="link8" name_joint="joint8" r_x="1" r_y="0" after_link="link9" I1="${IY}" I2="${IX}"/>
<xacro:model name_link="link9" name_joint="joint9" r_x="0" r_y="1" after_link="link10" I1="${IX}" I2="${IY}"/>
<xacro:model name_link="link10" name_joint="joint10" r_x="1" r_y="0" after_link="link11" I1="${IY}" I2="${IX}"/>
<xacro:model name_link="link11" name_joint="joint11" r_x="0" r_y="1" after_link="link12" I1="${IX}" I2="${IY}"/>

	<!--last model-->
	<link name="link12" >
	<visual>
		<origin rpy="0 0 0" xyz="0 0 ${0.8*body_l}"/>
		<geometry>
			<cylinder length="${body_l}" radius="${body_r}"/>
		</geometry>
		<material name="xwy">
			<color rgba="${color}"/>
		</material>
	</visual>	   
	<collision>
	        <origin rpy="0 0 0" xyz="0 0 ${0.8*body_l}"/>
		<geometry>
			<cylinder length="${body_l}" radius="${body_r}"/>
		</geometry>
	</collision>
	<inertial>
		<origin rpy="0 0 0" xyz="0 0 ${0.8*body_l}"/>
		<mass value="${mass}"/>
		<inertia ixx="${IY}" ixy="0.0" ixz="0.0" iyy="${IX}" iyz="0.0" izz="${IZ}"/>
	</inertial>
	</link>   
	<gazebo reference="link12">
		<material>Gazebo/Blue</material>
	</gazebo>
  
</robot>
